Workbook
Name _0x04_ReportDTCSnapshotRecordByDTCNumber_0x04_通过DTC报告Snapshot的记录: #REF!
Name _0x04_ReportDTCSnapshotRecordByDTCNumber_0x04_通过DTC报告Snapshot的记录: Services!$D$40
Name _0x06_ReportDTCExtendedDataRecordByDTCNumber_0x06_通过DTC报告扩展数据记录: #REF!
Name _0x06_ReportDTCExtendedDataRecordByDTCNumber_0x06_通过DTC报告扩展数据记录: Services!$D$41
Name _0x14: #REF!
Name _0x14: Services!$A$44
Name _0x22: #REF!
Name _0x22: Services!$A$30
Name _0x23: #REF!
Name _0x23: Services!$A$32
Name _0x27: #REF!
Name _0x27: Services!$A$12
Name _0x28: #REF!
Name _0x28: Services!$A$24
Name _0x2A: #REF!
Name _0x2A: Services!$A$34
Name _0x2E: #REF!
Name _0x2E: Services!$A$31
Name _0x2F: #REF!
Name _0x2F: Services!$A$45
Name _0x31: #REF!
Name _0x31: Services!$A$46
Name _0x3D: #REF!
Name _0x3D: Services!$A$33
Name Support_Customized_NRC_支持的自定义否定响应码: #REF!
Name Support_Customized_NRC_支持的自定义否定响应码: Services!$L$6

Sheet DTCInfo
A1: Return
A2: Diagnostic Questionnaire - GroupOfDTC
A5: Service ID | B5: DTC Group(hex) | C5: Group Description | D5: Supported by ECU | E5: Remarks | F5: FVT Require
A7: 0x14 | B7: 0xFFFF33 | C7: Emissions-related systems | D7: N | F7: U
B8: 0x100000 | C8: Powertrain group | D8: N | F8: U
B9: 0x400000 | C9: Chassis group | D9: N | F9: U
B10: 0x800000 | C10: Body group | D10: N | F10: U
B11: 0xC00000 | C11: Network communication group | D11: N | F11: U
B12: 0xFFFFFF | C12: All DTC group | D12: Y | F12: M
A14: Diagnostic Questionnaire - DTC Status
A17: Bit Field | B17: Bit Description | C17: Bit State Definition | D17: Supported by ECU | E17: Remarks | F17: FVT Require
A18: 0 | B18: Test failed | C18: 0=False 1=True | D18: Y | F18: M
A19: 1 | B19: Test failed this monitoring cycle | C19: 0=False 1=True | D19: Y | F19: U
A20: 2 | B20: Pending DTC | C20: 0=False 1=True | D20: Y | F20: M
A21: 3 | B21: Confirmed DTC | C21: 0=False 1=True | D21: Y | F21: M
A22: 4 | B22: Test not completed since last clear | C22: 0=False 1=True | D22: N | F22: U
A23: 5 | B23: Test failed since last clear | C23: 0=False 1=True | D23: N | F23: U
A24: 6 | B24: Test not completed this monitoring cycle | C24: 0=False 1=True | D24: Y | F24: U
A25: 7 | B25: Warning indicator requested | C25: 0=False 1=True | D25: N | F25: U

Sheet GeneralInfo
A2: Diagnostic Questionnaire - General information
A5: General information
A6: Car model selection | B6: ECU Information
B7: Name | C7: Value | D7: Unit
A8: OTHER | B8: ECU Name | C8: Fusion ECU
A10: CAN(FD) Information
A11: Name | B11: Value | C11: Unit | D11: FVT Require | E11: FVT Normative Values
A12: Support | B12: NO | C12: ! | D12: M
A13: Protocol | B13: CANFD | D13: M
A14: CAN ID Format | B14: Standard | D14: C
A15: CAN Physical Request ID | B15: 0x680 | D15: M
A16: CAN Functional Request ID | B16: 0x7D0 | D16: M
A17: CAN Response ID | B17: 0x600 | D17: M
A18: N_Cr | B18: 150 | C18: ms | D18: M | E18: 150ms
A19: N_Cs | B19: 100 | C19: ms | D19: M | E19: ≤100ms
A20: N_Br | B20: 100 | C20: ms | D20: M | E20: ≤100ms
A21: N_Bs | B21: 150 | C21: ms | D21: M | E21: 150ms
A22: P2(Client) | C22: ms | D22: C | E22: <150ms
A23: P2*(Client) | C23: ms | D23: C | E23: <5500ms
A24: S3(Client) | C24: ms | D24: C | E24: <2000ms
A25: STmin(Client) | C25: ms | D25: C | E25: 0ms
A26: BlockSize(Client) | D26: C | E26: 0
A27: P2(ECU) | B27: 50 | C27: ms | D27: M | E27: <50ms
A28: P2*(ECU) | B28: 5000 | C28: ms | D28: M | E28: <5000ms
A29: S3(ECU) | B29: 5000 | C29: ms | D29: M | E29: <5000ms
A30: STmin(ECU) | B30: 15 | C30: ms | D30: M | E30: ≤1ms
A31: BlockSize(ECU) | B31: 0 | D31: M | E31: 0
A32: Buffer | B32: 500 | C32: bytes | D32: C
A33: Baudrate | B33: 2000 | C33: kps | D33: M | E33: =IF(GeneralInfo!A8="EBUS","250k","500k") -> 500k
A34: CANFDBaudrate | B34: 64 | C34: kps | D34: M | E34: 2M
A35: CANFD DLC | B35: 64 | D35: C | E35: 8~64
A37: Doip Information
A38: Name | B38: Value | C38: Unit | D38: FVT Require | E38: FVT Normative Values
A39: Support | B39: YES | D39: C
A40: DoIP Logical Tester Address | B40: 0x0E00
A41: DoIP Logical ECU Address | B41: 0x0680
A42: DoIP Logical Functional Address | B42: 0xEFFF
A43: P6 | B43: 1000 | C43: ms
A44: P6* | B44: 5000 | C44: ms
A45: P2(Client) | B45: 2000 | C45: ms
...

Sheet Cover
V1: Commercial vehicle | W1: Y | X1: Unsigned | Y1: Hex | Z1: Request
V2: Passenger Cars | W2: N | X2: Signed | Y2: Decimal | Z2: Response
X3: Hex | Y3: BCD
A4: LOGO | X4: BCD | Y4: ASCII
X5: ASCII
A6: Diagnostic Specificaion | D6: Date: | E6: 2025/04/21
A12: ECU (Module) DATA
A13: ECU Name Acronym | B13: CAN Rx/Tx Ids in Hex | C13: Diagnostic Com. Link | D13: Supplier | E13: ECU Variant
A14: =#REF! -> #REF! | B14: 0x680 | C14: =#REF! -> #REF! | D14: FVT
B15: 0x7D0
B16: 0x600
A17: Diagnostic Specifications | E17: Part Number / Version
A18: [ 1 ] FSE-F00005 Requirement Specification Diagnostic Communication | E18: Part Number: D31L: 29710HA100 D31L24: 29710HA110 D31F25: 29710HA200 D31H: 29710HC100 D21: 29710BA100 Foxtorn Pi: 29710HA110
E19: HW:
E20: SW:

Sheet Introduction
A2: 版本 | B2: 日期 | C2: 作者 | D2: 審查人員 | E2: 狀態 | F2: 修改章節 | G2: 修改說明 | L2: Introduction
A3: A | B3: 2022/02/22 | C3: Yi Jun | D3: David Yu | E3: release | F3: null | G3: 發布初始版本Demo | L3: Cvt | M3: Convention, the parameter conventions described in following table.
B4: 2022/02/25 | C4: Yi Jun | D4: MinHungWang | E4: release | F4: DTCList | G4: 加入counter | L4: Type | M4: Name | O4: Description
B5: 2022/03/14 | C5: Yi Jun | D5: MinHungWang | E5: release | F5: GeneralInfo | G5: 1. Support欄位預設yes，FVT要求為M 2. Protocol為CAN，DLC為8 3. CAN Functional Request ID在Extended下可輸入其他值 | L5: M | M5: Mandatory | O5: The parameter shall be present by ECU
A6: B | B6: 2022/03/17 | C6: Yi Jun | D6: MinHungWang | E6: release | F6: Service | G6: 診斷模式控制0x03，安全問訪級別01刪除 | L6: C | M6: Conditional | O6: The parameter can be present by ECU, based on certain criteria
A7: C | B7: 2022/07/25 | C7: Sam Wei | D7: Sam Tso | E7: release | F7: 1.27Service 2.DTCList 3.Snapshot 4.ExtendedData 5.DIDIList 6.DIDData | G7: 1. 27Service 演算法改為AES-128，SEED/KEY 改為16Bytes 2.DTCList Busoff 內容修正 3.Snapshot範例更新 4.ExtendedData 範例更新 5.DIDList更新(新增多組DID及移除不適用DID) 6.DIDData更新(新增多組DID及移除不適用DID) | L7: U | M7: User option | O7: The parameter may or may not be present, depending on dynamic usage by the user.
A8: D | B8: 2022/10/28 | C8: Fu Wei Huang | D8: Fu Wei Huang | E8: release | F8: 1. GeneralInfo 2. Services 3. 27Service 4. 28Service 5. DTCInfo | G8: 1. 取消Client欄位底色，後續ECU無需填寫此欄位。 2-1. 將各欄位預期填寫內容調整為預設值。 2-2. ISO規範Level為requestSeed之hex值，故修改原L2為L3。 3. 新增key填寫欄位。 4. 將各欄位預期填寫內容調整為預設值。 5. NRC 5. 更新DTC Status的Mandatory項目。
A9: E | B9: 2022/11/03 | C9: Fu Wei Huang | D9: Fu Wei Huang | E9: release | F9: 1. 27Service 2. DIDIList 3. DIDData 4. Bootloader 5. NRC | G9: 1. 欄位A16誤記更正。 2. 新增DID F180。 3. 新增DID F180。 4. 開放空白欄位填寫資訊。 5. 開放供應商填寫自訂義NRC資訊。 | L9: ASC | M9: ASCII Encoded.
A10: F | B10: 2022/12/12 | C10: Fu Wei Huang | D10: Fu Wei Huang | E10: release | F10: 1. Cover 2. Revision 3. GenetalInfo 4. Services 5. 27Service 6. 28Service 7. DTCInfo 8. DTCIList 9. Snapshot 10. ExtendedData 11. DIDIList 12. DIDData 13. 2FServices 14. 31Services 15. 23_3DServices 16. 2AServices | G10: 1. 開放空白欄位填寫資訊、新增欄位E18、E19、E20填寫資訊。 2. 開放空白欄位填寫資訊。 3. 開放空白欄位填寫資訊。 4. 開放空白欄位填寫資訊、欄位K24、K25、K26、K27、F37、F38、F39、F40、F41、F42誤記更正。 5. 開放空白欄位填寫資訊。 6. 開放空白欄位填寫資訊。 7. 開放空白欄位填寫資訊、新增黃底標註。 8. 開放空白欄位填寫資訊、新增黃底標註。 9. 開放空白欄位填寫資訊、新增黃底標註。 10. 開放空白欄位填寫資訊、新增黃底標註。 11. 開放空白欄位填寫資訊、新增黃底標註、更新欄位C7、C8、C12、C14、C15、C16、C17、C21。 12. 開放空白欄位填寫資訊、新增黃底標註、更新Column W、欄位P20、T20、U20、V20、P22、T22、U22、V22。 13. 開放空白欄位填寫資訊、新增黃底標註。 14. 開放空白欄位填寫資訊、新增黃底標註。 15. 開放空白欄位填寫資訊、新增黃底標註。 16. 開放空白欄位填寫資訊、新增黃底標註。 | L10: VSIE | M10: Vehicle Software Integration Engineer
A11: G | B11: 2023/1/5 | C11: Fu Wei Huang | D11: Fu Wei Huang | E11: release | F11: 1. Cover 2. DTCList 3. Snapshot 4. DIDData 5. 2FServices 6. 31Services 7. 23_3DServices 8. Bootloader 9. EOL 10. Calibration | G11: 1. 更新E18、E19、E20填寫資訊。 2. 新增column F、column N、column O、column S、column T、column V、column W。 3-1. 新增A11、A13、B11、B13填寫資訊。 3-2. 更新G12填寫方式。 4. 更新F11、F13、F15、F17、F19、F21、F23、F25、F29填寫方式。 5. 更新I14填寫方式。 6. 更新H11、H12填寫方式。 7. 更新F12、F15、F19、F20填寫方式。 8. 新增燒錄檔格式說明。 9. 新增sheet。 10. 新增sheet。 | L11: BCD | M11: Binary Coded Decimal (Numeric Signal)
A12: H | B12: 2023/1/18 | C12: Fu Wei Huang | D12: Fu Wei Huang | E12: release | F12: 1. Snapshot 2. ExtendedData 3. DIDData 4. 2FServices 5. 31Services 6. 23_3DServices 7. 2AServices | G12: 1-1. 刪除column F、column G；新增column F、column G、column H。 1-2. 更新N10資訊。 2. 刪除column F、column G；新增column F、column G、column H。 3. 刪除column E、column F；新增column E、column F、column G。 4. 刪除column H、column I；新增column H、column I、column J。 5. 刪除column G、column H；新增column G、column H、column I。 6. 刪除column E、column F；新增column E、column F、column G。 7. 刪除column E、column F；新增column E、column F、column G。 | L12: BLN | M12: Boolean
A13: I | B13: 2023/2/3 | C13: Fu Wei Huang | D13: Fu Wei Huang | E13: release | F13: 1. DTCList 2. Snapshot 3. ExtendedData 4. DIDData 5. 2FServices 6. 31Services 7. 23_3DServices 8. 2AServices | G13: 1. 配合JAMA FRS填寫需求， 1-1. 移動column G、column H 、column I、column J、column R、column S、column T、column U、column V。 1-2. 刪除column M、column N、column O、column P、column Q。 1-3. 新增column S、column T、column U、column V、column W、column X、column Y、column Z、column AA、column AB。 2-1. 刪除column G(Bit Length)、column H(Start Bit)；新增column G(MSB bit(Motorola))、column H(LSB bit(Motorola))。 2-2. 欄位”J16”從1調整為0、欄位”K16”從24調整為23。 3. 刪除column G(Bit Length)、column H(Start Bit)；新增column G(MSB bit(Motorola))、column H(LSB bit(Motorola))。 4-1. 刪除column F(Bit Length)、column G(Start Bit)；新增column F(MSB bit(Motorola))、column G(LSB bit(Motorola))。 4-2. 欄位”I33”從1調整為0、欄位”J33”從24調整為23。 4-3. 欄位”B8”新增"自定義DID建議範圍"。 5. 刪除column I(Bit Length)、column J(Start Bit)；新增column I(MSB bit(Motorola))、column J(LSB bit(Motorola))。 6. 刪除column H(Bit Length)、column I(Start Bit)；新增column H(MSB bit(Motorola))、column I(LSB bit(Motorola))。 7. 刪除column F(Bit Length)、column G(Start Bit)；新增column F(MSB bit(Motorola))、column G(LSB bit(Motorola))。 8. 刪除column F(Bit Length)、column G(Start Bit)；新增column F(MSB bit(Motorola))、column G(LSB bit(Motorola))。 | L13: DRE | M13: Design Release Engineer
A14: J | B14: 2023/7/18 | C14: Fu Wei Huang | D14: Fu Wei Huang | E14: release | F14: 1. GeneralInfo 2. Services 3. DTCInfo 4. Snapshot 5. ExtendedData 6. DIDList 7. DIDData 8. 2FService 9. 31Service 10. Bootloader | G14: 1. 新增row 32、row 51註記Buffer。 2. 對應新版FSE"FSE-F00005 Requirement Specification Diagnostic Communication revision D_20230612"， 2-1. 欄位N31、N45、N48、N49、N50調整為M。 2-2. 刪除欄位M21、M23。 2-3. 欄位N21調整為U。 2-4. 欄位C32、C33、C34、C44、C51、E21、E22、E25、E26、E39、E46、E47、G32、I32、J32、J51、K32、K51調整為空白。 3. 欄位D7、D8、D9、D10、D11、D19、D22、D23、D24、D25調整為空白。 4-1. 誤記更正 4-1-1. 欄位G10、G12調整為7。 4-1-2. 欄位H12調整為8。 4-2. 補充欄位N10、N12內容。 5. 補充欄位N10、N12內容。 6. 對應新版FSE"FSE-F00005 Requirement Specification Diagnostic Communication revision D_20230612"， 6-1. 欄位H10調整為M。 6-2. 新增row 22、23。 6-3. 欄位C11、G11、C13、G13調整為空白。 7-1. 誤記更正、對應新版FSE"FSE-F00005 Requirement Specification Diagnostic Communication revision D_20230612"， 7-1-1. 刪除欄位V20、V22；欄位W20、W22調整為01。 7-1-2. 欄位N27調整為 0x0：OFF 0x1：OFF-Charging 0x2：OFF-After-Run 0x3：STANDBY 0x4：ON 0x5：READY 7-1-3. 欄位T36、D10、E11、F11、G11、D16、E17、F17、G17、D18、E19、F19、G19、D24、E25、F25、G25、D36、E37、F37、G37、D38、E39、F39、G39、S36調整為空白。 7-1-4. 新增row 38~43。 7-1-5. 欄位D14調整為146、G15調整為40。 7-1-6. 欄位R10、R36調整為01/03。 7-1-7. 欄位S12、S38、S40、S42調整為02。 7-2. 補充欄位M11、M13、M15、M17、M19、M21、M23、M25、M27、M29內容。 8. 補充欄位P15、P16、P17、P19內容。 9-1. 對應新版FSE"FSE-F00005 Requirement Specification Diagnostic Communication revision D_20230612"， 9-1-1. 移除0x2203，刪除row 18~row 21。 9-1-2. 欄位P14內容調整為 0x01: erase correctly. 0x00: erase incorrectly. 9-1-3. 欄位P17內容調整為 0x01: CRC check correctly. 0x00: CRC check incorrectly. 9-2. 補充欄位O11、O12、O14、O17、O19、O21內容。 10. 對應新版FSE"FSE-F00005 Requirement Specification Diagnostic Communication revision D_20230612"，更新Bootloader流程圖。 | L14: DTC | M14: Diagnostic Trouble Code
A15: K | B15: 2023/8/24 | C15: Fu Wei Huang | D15: Fu Wei Huang | E15: release | F15: 1. Cover 2. Introduction 3. GeneralInfo 4. Services 5. 28Service 6. DTCList 7. Snapshot 8. ExtendedData 9. DIDList 10. DIDData 11. 2FService 12. 31Service 13. 23_3DService 14. 2AService | G15: 1-1. 欄位J6調整為空白。 1-2. 調整欄位A14內容。 1-3. 欄位E14、E15、E16調整為空白。 1-4. 欄位G15、H15、I15、J15調整為空白。 2. 欄位G14誤記更正(7-1-5. 、9-2)。 3-1. 新增A6、A7、A8。 3-2. 調整欄位B8、E33內容。 4. 欄位H8、H10調整為空白。 5. 欄位E7、F7、D8、E8、F8、D9、E9、F9、E10、F10調整為空白。 6. 欄位X8調整為"Same as DTC enable criteria."。 7-1. 刪除column N"Display Radix"。 7-2. column M"Data Type"下拉選項調整為Unsigned、Signed、Hex、BCD、ASCII。 7-3. 新增column O、P內容。 7-4. 調整row10、12內容，依各車型資訊進行填寫。 7-5. 欄位Q9、Q12、Q14調整為M(Signal data refer to message matrix.)。 8-1. 刪除column N"Display Radix"。 8-2. column M"Data Type"下拉選項調整為Unsigned、Signed、Hex、BCD、ASCII。 8-3. 欄位O10、012調整為1。 8-4. 欄位D11調整為"Report number of aging counter"。 8-5. 欄位I12調整為"Aging Counter"。 8-6. "DTC Identifier"調整至column P。 9. 調整欄位G6內容。 10-1. 刪除column M"Display Radix"。 10-2. column L"Data Type"下拉選項調整為Unsigned、Signed、Hex、BCD、ASCII。 10-3. 新增column N、O內容。 10-4. 調整row27、row29內容，依各車型資訊進行填寫。 11-1. 刪除column F"Request and Reponse"。 11-2. 刪除column P"Display Radix"。 11-3. column N"Data Type"下拉選項調整為Unsigned、Signed、Hex、BCD、ASCII。 11-4. 新增column P、Q內容。 11-5. 調整InputOutputControlParameter呈現方式。 11-6. 欄位N18調整為Hex。 11-7. 欄位N19、20、21、22調整為Unsigned。 11-8. 欄位P22調整為1。 12-1. 刪除column O"Display Radix"。 12-2. column N"Data Type"下拉選項調整為Unsigned、Signed、Hex、BCD、ASCII。 12-3. 新增column P、Q內容。 12-4. 新增B13、C13、D13、B16、C16、D16。 12-5. 調整欄位U10、U15內容。 13-1. 刪除column M"Display Radix"。 13-2. column L"Data Type"下拉選項調整為Unsigned、Signed、Hex、BCD、ASCII。 13-3. 新增column N、O內容。 14-1. 刪除column M"Display Radix"。 14-2. column L"Data Type"下拉選項調整為Unsigned、Signed、Hex、BCD、ASCII。 14-3. 新增column N、O內容。
A16: L | B16: 2024/5/16 | C16: Fu Wei Huang | D16: Fu Wei Huang | E16: release | F16: 1. Cover 2. Revision 3. GeneralInfo 4. Services 5. 27Service 6. 28Service 7. DTCInfo 8. DTCList 9. DTCData 10. Snapshot 11. ExtendedData 12. DIDList 13. DIDData 14. 2FService 15. 31Service 16. 23_3DService 17. 2AService 18. Bootloader 19. EOL 20. Calibration 21. NRC 22. OIL | G16: 1. 移除column G~J。 2. 移除中文字體。 3-1. 移除中文字體。 3-2. 參考"FSE-F00005 Requirement Specification - Diagnostic Communication revision E_20240516.docx"，欄位E30調整為"≤1ms"。 3-3. 更新row 55內容。 4-1. 移除中文字體。 4-2. 新增欄位L9、欄位M9內容。 4-3. 更新欄位K21~K23內容。 5-1. 移除中文字體。 5-2. 新增column G~M。 6. 移除中文字體。 7. 移除中文字體。 8. 新增sheet"DTCList" 9. 新增sheet"DTCData" 10-1. 移除中文字體。 10-2. 更新欄位I12、K12、O12內容。 11-1. 移除中文字體。 11-2. 更新欄位C9、Q9、C11、Q11內容。 12-1. 移除中文字體。 12-2. 新增column F~S。 13-1. 移除中文字體。 13-2. 更新欄位H29、J29、N29內容。 14. 移除中文字體。 15-1. 移除中文字體。 15-2. 新增欄位F4、row16內容。 16. 移除中文字體。 17. 移除中文字體。 18-1. 移除中文字體。 18-2. 更新row1內容。 19. 移除中文字體。 20. 移除中文字體。 21. 移除中文字體。 22. 移除中文字體。
A17: M | B17: 2025/2/10 | C17: Sam Tso | D17: Sam Tso | E17: release | F17: 1. Revision 2. GeneralInfo 3. Services 4. DTCInfo 5. DTCData | G17: 1. Revision 1-1. 新增M版履歷 2. GeneralInfo 2-1. 移除Client端時間參數欄位 2-2. 新增ZEVonUDS欄位 3. Services 3-1. 新增0x19 42 ReportWWHOBDDTCByMaskRecord欄位(ZEVonUDS) 4. DTCInfo 4-1. 新增DTC Group 0xFFFF33 Remark(ZEVonUDS) 4-2. 新增DTC Status bit 0,1,2,3,4,6 Remark(ZEVonUDS) 4-3. 新增Diagnostic Questionnaire - DTCFormatIdentifier(ZEVonUDS) 5. DTCData 5-1. DTC Level修改為DTC Severity(ZEVonUDS)

Sheet Revision
A1: v02.23_2025/04/21_R0
A2: Revision Management
A5: Revision | B5: Date | C5: Author | D5: Changes Section | E5: Changes Comments
A6: v1.0 | B6: 2023/01/01 | C6: 陳冠廷 | D6: null | E6: 初版發行
A7: v1.1 | B7: 2023/01/01 | C7: 陳冠廷 | E7: 內容修正
A8: v1.2 | B8: 2023/05/04 | C8: 陳冠廷 | E8: 內容修正
A9: v1.3 | B9: 2023/06/01 | C9: 張晉圖 | D9: ALL | E9: 重新整理
A10: v1.4 | B10: 2023/07/17 | C10: 張晉圖 | D10: DTCList、DIDdata、DIDList、EOL | E10: 內容修正
A11: v1.5 | B11: 2023/07/19 | C11: 張晉圖 | D11: DTCList、DIDdata、DIDList、Calibration、 GeneralInfo、Snapshot、2FService | E11: 內容修正
A12: v1.6 | B12: 2023/07/21 | C12: 張晉圖 | D12: DTCList、DIDdata、DIDList | E12: 內容修正
A13: v1.7 | B13: 2023/07/25 | C13: 張晉圖 | D13: DIDdata、DIDList、Services、27Service、2FService | E13: 內容修正
A14: v1.8 | B14: 2023/07/27 | C14: 張晉圖 | D14: DIDdata、DIDList、Services、EOL、Calibration、 GeneralInfo、 | E14: 內容修正
A15: v1.9 | B15: 2023/07/31 | C15: 張晉圖 | D15: EOL、DTCList | E15: 內容修正
A16: v1.10 | B16: 2023/09/18 | C16: 張晉圖 | D16: DTCList | E16: DTCList: B100903~B100906 誤記訂正
A17: v1.11 | B17: 2023/09/26 | C17: 張晉圖 | D17: GeneralInfo : CANFD DLC: 8 -> 64 | E17: 內容修正
A18: v1.12 | B18: 2023/11/10 | C18: 張晉圖 | D18: DIDdata、DIDList、EOL、 Calibration 27Service: Add security level 5 key GeneralInfo : DoIP Address from 0E80 to 0E00 | E18: 內容修正
A19: v1.13 | B19: 2023/12/14 | C19: 張晉圖 | D19: 31Service (IMU)、 DIDdata、DIDList、EOL、 Calibration 27Service: Add security level 5 key | E19: 1、內容修正 2、採用 K版格式
A20: v1.14 | B20: 2024/2/16 | C20: 張晉圖 | D20: DTCInfo、DTCList、DIDdata、DIDList、 Services、28Service、2FService | E20: 內容修正
... A55: v02.23_2025/04/21_R0 | B55: 2025/04/21 | C55: 張晉圖 | D55: DIDList、DIDData、DTCData | E55: 1. FoxtronPi 誤記訂正 DIDList 0x0202 (WriteRandomNumberDKC) 2. FoxtronPi 刪除 DID : FoxPi_Steering_Ctrl、FoxPi_Shifter_Ctrl (DIDList、DIDData) 3. FoxtronPi 新增 DID : FoxPi_Ctrl_Enable_Switch (DIDList、DIDData) 4. FoxtronPi 更名 DID & 內容新增 : FoxPi_Speed_Ctrl -> FoxPi_Driving_Ctrl (DIDList、DIDData) 5. VND DTCData 內容修正 (DTCData)

Sheet GeneralInfo2
A2: Diagnostic Questionnaire - General information
A5: General information
A6: Name | B6: Value | C6: Remark
A7: ECU Name | B7: Fusion ECU
A8: Car model selection | B8: Passenger Cars
A9: ZEVonUDS | B9: YES | C9: D31F25/D21/D31H
A11: CAN(FD) Information
A12: Name | B12: Value | C12: Unit | D12: FVT Require | E12: FVT Normative Values
A13: Support | B13: NO | C13: ! | D13: M
A14: Protocol | B14: CANFD | D14: M
A15: CAN ID Format | B15: Standard | D15: C
A16: CAN Physical Request ID | B16: 0x680 | D16: M
A17: CAN Functional Request ID | B17: 0x7D0 | D17: M
A18: CAN Response ID | B18: 0x600 | D18: M
A19: N_Cr | B19: 150 | C19: ms | D19: M | E19: 150ms
A20: N_Cs | B20: 100 | C20: ms | D20: M | E20: ≤100ms
A21: N_Br | B21: 100 | C21: ms | D21: M | E21: ≤100ms
A22: N_Bs | B22: 150 | C22: ms | D22: M | E22: 150ms
A23: P2(ECU) | B23: 50 | C23: ms | D23: M | E23: <50ms
A24: P2*(ECU) | B24: 5000 | C24: ms | D24: M | E24: <5000ms
A25: S3(ECU) | B25: 5000 | C25: ms | D25: M | E25: <5000ms
A26: STmin(ECU) | B26: 15 | C26: ms | D26: M | E26: ≤1ms
A27: BlockSize(ECU) | B27: 0 | D27: M | E27: 0
A28: Buffer | B28: 500 | C28: bytes | D28: C
A29: Baudrate | B29: 2000 | C29: kps | D29: M | E29: =IF(GeneralInfo2!B8="Commercial vehicle","250k","500k") -> 500k
A30: CANFDBaudrate | B30: 64 | C30: kps | D30: M | E30: 2M
A31: CANFD DLC | B31: 64 | D31: C | E31: 8~64
A33: Doip Information
A34: Name | B34: Value | C34: Unit | D34: FVT Require | E34: FVT Normative Values
A35: Support | B35: YES | D35: C
A36: DoIP Logical Tester Address | B36: 0x0E00
A37: DoIP Logical ECU Address | B37: 0x0680
A38: DoIP Logical Functional Address | B38: 0xEFFF
A39: P6 | B39: 1000 | C39: ms
A40: P6* | B40: 5000 | C40: ms
A41: P2(ECU) | B41: 1000 | C41: ms
A42: P2*(ECU) | B42: 5000 | C42: ms
A43: S3(ECU) | B43: 5000 | C43: ms
A44: Buffer | B44: 16384 | C44: bytes
A46: Security Access Parameter Information
...

Sheet Services
A2: Diagnostic Questionnaire Diagnostic Services
A6: Service ID | B6: Diagnostic Services Name | C6: Diagnostic Services Supported by ECU | D6: Sub-functions | E6: Sub-function supported by ECU | F6: SPRMB | G6: Application Software Diagnostic Session | H6: Boot Software Diagnostic Session | I6: Security Level | J6: Comm Types | L6: Support Customized NRC | M6: Comments | N6: FVT Require
J7: Phy | K7: Func
A8: 0x10 | B8: DiagnosticSessionControl | C8: Y | D8: 0x01 DefaultSession | E8: Y | F8: Y | G8: 01/03 | H8: N | I8: N | J8: Y | K8: Y | N8: M
D9: 0x02 ProgrammingSession | E9: Y | F9: Y | G9: 03 | H9: N | I9: 01 | J9: Y | K9: Y | N9: M
D10: 0x03 ExtendedDiagnosticSession | E10: Y | F10: Y | G10: 01/03 | H10: N | I10: N | J10: Y | K10: Y | N10: M
N11: U
A12: 0x27 | B12: SecurityAccess | C12: Y | D12: 0x01 requestSeed (Level 1) | E12: Y | F12: N | G12: 03 | H12: N | I12: N | J12: Y | K12: N | N12: M
D13: 0x02 sendKey (Level 1) | E13: Y | F13: N | G13: 03 | H13: N | I13: N | J13: Y | K13: N | N13: M
D14: 0x03 requestSeed (Level 3) | E14: Y | F14: N | G14: 03 | H14: 02 | I14: N | J14: Y | K14: N | N14: M
D15: 0x04 sendKey (Level 3) | E15: Y | F15: N | G15: 03 | H15: 02 | I15: N | J15: Y | K15: N | N15: M
D16: 0x05 requestSeed (Level 5) | E16: Y | F16: N | G16: 03 | H16: N | I16: N | J16: Y | K16: N | N16: U
D17: 0x06 sendKey (Level 5) | E17: Y | F17: N | G17: 03 | H17: N | I17: N | J17: Y | K17: N | N17: U
N18: U
N19: U
A20: 0x3E | B20: TesterPresent | C20: Y | D20: 0x00 ZeroSubFunction | E20: Y | F20: Y | G20: 01/03 | H20: N | I20: N | J20: Y | K20: Y | N20: M
A21: 0x11 | B21: EcuReset | C21: Y | D21: 0x01 HardReset | E21: Y | F21: Y | G21: 03 | H21: N | I21: 01/03 | J21: Y | K21: N | N21: U
D22: 0x02 KeyOffOnReset | E22: N | F22: N | G22: 03 | H22: N | I22: 01/03 | J22: Y | K22: N | N22: U
D23: 0x03 softReset | E23: Y | F23: Y | G23: 03 | H23: N | I23: 01/03 | J23: Y | K23: N | N23: M
A24: 0x28 | B24: CommunicationControl | C24: Y | D24: 0x00 EnableRxAndTx | E24: N | F24: Y | G24: 03 | H24: N | I24: 01 | J24: Y | K24: Y | N24: M
D25: 0x01 EnableRxAndDisableTx | E25: N | F25: Y | G25: 03 | H25: N | I25: 01 | J25: Y | K25: Y | N25: U
D26: 0x02 DisableRxAndEnableTx | E26: N | F26: Y | G26: 03 | H26: N | I26: 01 | J26: Y | K26: Y | N26: U
D27: 0x03 DisableRxAndTx | E27: N | F27: Y | G27: 03 | H27: N | I27: 01 | J27: Y | K27: Y | N27: M
A28: 0x85 | B28: ControlDTCSetting | C28: Y | D28: 0x01 ON | E28: Y | F28: Y | G28: 03 | H28: N | I28: 01 | J28: Y | K28: Y | N28: M
D29: 0x02 OFF | E29: Y | F29: Y | G29: 03 | H29: N | I29: 01 | J29: Y | K29: Y | N29: M
A30: 0x22 | B30: ReadDataByIdentifier | C30: Y | E30: Y | F30: N | G30: 01/03 | H30: N | I30: N | J30: Y | K30: Y | N30: M
A31: 0x2E | B31: WriteDataByIdentifier | C31: Y | E31: Y | F31: N | G31: 03 | H31: N | I31: 03/05 | J31: Y | K31: N | N31: M
A32: 0x23 | B32: ReadMemoryByAddress | C32: N | E32: N | F32: N | G32: N | H32: N | I32: N | J32: N | K32: N | N32: U
A33: 0x3D | B33: WriteMemoryByAddress | C33: N | E33: N | F33: N | G33: N | H33: N | I33: N | J33: N | K33: N | N33: U
A34: 0x2A | B34: ReadDataByPeriodicIdentifier | C34: N | E34: N | F34: N | G34: N | H34: N | I34: N | J34: N | K34: N | N34: U
A35: 0x2C | B35: DynamicallyDefineDataIdentifier 动态定义数据标识符 | C35: N | D35: 0x01 defineByIdentifier 0x01 通过标识符定义 | E35: N | H35: N | I35: N | J35: Y | K35: N
D36: 0x03 clearDynamicallyDefinedDataIdentifier 0x03 清除动态定义数据标识符 | E36: N | H36: N | I36: N | J36: Y | K36: N | N36: M
A37: 0x19 | B37: ReadDTCInformation | C37: Y | D37: 0x01 ReportNumberOfDTCByStatusMask | E37: Y | F37: N | G37: 01/03 | H37: N | I37: N | J37: Y | K37: Y | N37: U
D38: 0x02 ReportDTCByStatusMask | E38: Y | F38: N | G38: 01/03 | H38: N | I38: N | J38: Y | K38: Y | N38: M
D39: 0x03 ReportDTCSnapshotIdentification | E39: N | F39: N | G39: 01/03 | H39: N | I39: N | J39: Y | K39: Y | N39: U
D40: 0x04 ReportDTCSnapshotRecordByDTCNumber | E40: Y | F40: N | G40: 01/03 | H40: N | I40: N | J40: Y | K40: Y | N40: M
D41: 0x06 ReportDTCExtendedDataRecordByDTCNumber | E41: N | F41: N | G41: 01/03 | H41: N | I41: N | J41: Y | K41: Y | N41: U
D42: 0x0A ReportSupportedDTC | E42: Y | F42: N | G42: 01/03 | H42: N | I42: N | J42: Y | K42: Y | N42: M
D43: 0x42 ReportWWHOBDDTCByMaskRecord | E43: Y | F43: N | G43: 01/03 | H43: N | I43: N | J43: Y | K43: Y | N43: ZEVonUDS
A44: 0x14 | B44: ClearDiagnosticInformation | C44: Y | E44: Y | F44: Y | G44: 01/03 | H44: N | I44: N | J44: Y | K44: Y | N44: M
...

Sheet 27Service
A1: Return
A2: Diagnostic Questionnaire Seed and Key
A4: Service ID | B4: Diagnostic Services Name | C4: Sub-functions | D4: Seed and Key | F4: Comments | G4: Part number & model
G5: 29710HA100 | H5: 29710HA110 | I5: 29710HA200 | J5: 29710HC100 | K5: 29710BA100 | L5: 29710HA110
D6: Length of the seed | E6: Length of the Key | G6: D31L | H6: D31L24 | I6: D31F25 | J6: D31H | K6: D21 | L6: Foxtorn Pi
A7: 0x27 | B7: SecurityAccess | C7: =IF(Services!D12="","",Services!D12) -> 0x01 requestSeed (Level 1) | D7: 16 | F7: AES-128 ECB mode
C8: =IF(Services!D13="","",Services!D13) -> 0x02 sendKey (Level 1) | E8: 16
C9: =IF(Services!D14="","",Services!D14) -> 0x03 requestSeed (Level 3) | D9: 16 | F9: AES-128 ECB mode
C10: =IF(Services!D15="","",Services!D15) -> 0x04 sendKey (Level 3) | E10: 16
C11: =IF(Services!D16="","",Services!D16) -> 0x05 requestSeed (Level 5)
C12: =IF(Services!D17="","",Services!D17) -> 0x06 sendKey (Level 5)
C13: =IF(Services!D18="","",Services!D18)
C14: =IF(Services!D19="","",Services!D19)
A15: Level 1 key | G15: 24 43 26 46 29 4A 40 4E 63 52 66 55 6A 58 6E 32 | H15: D2 E3 99 BB C7 AF 8C C0 3A 3C 16 1A 22 DB 85 29 | I15: E2 D4 54 1D 55 58 31 17 D9 45 BE 46 B2 47 0C F9 | J15: B7 68 D9 63 24 75 F2 99 8C B6 BC AC D7 B7 D4 62 | K15: 0A 8A 26 4E 7B B1 A9 3B D5 ED CE 90 E0 18 C7 D5 | L15: A8 AB 5F 37 72 3A F4 D2 2B BC 7F 47 D8 0F 8E 39
A16: Level 3 key | G16: 6B 58 70 32 73 35 76 38 78 2F 41 3F 44 28 47 2B | H16: 01 B8 4D CB 8B 90 1B 4E 9D 57 8F E1 C0 FD C7 0E | I16: D6 15 93 0B 8A E0 6A 88 CF CB 85 92 29 4E 92 E7 | J16: A7 CC F5 E7 1C 8F 8F 5F 1B E5 A8 ED DC 73 83 B1 | K16: 22 23 6E 27 96 55 E5 7D D0 60 A4 29 2B 8F 0A 71 | L16: 8D A7 6F A3 94 11 62 4E 44 8D 24 03 F8 F3 4E D5
A17: Level 5 key | G17: 8F 65 E8 2F F6 5F 69 49 20 A1 A1 EF AB BF 2F E0 | H17: D9 39 BD 42 AF 53 4D 58 3D F3 F6 EA 57 9E DA DE | I17: DE 4F 51 E0 39 68 81 24 E0 12 8F E7 19 4D F3 F7 | J17: 1F 34 DD 55 C9 C7 1B 68 16 F9 CF FB 93 B7 AB 40 | K17: 6F 3B 53 4E 76 45 C0 7F 93 3F 84 FB 2D 89 B9 B1 | L17: 74 ED B0 45 DC BB CF 1F E5 53 B5 3B CF 46 46 91

Sheet 28Service
A1: Return
A2: Diagnostic Questionnaire Communication Contorl Type
A5: Service ID | B5: Diagnostic Services Name | C5: Sub-functions | D5: Communication Contorl Type | G5: Comments
D6: NCM 0x01 | E6: NMCM 0x02 | F6: NCM_NMCM 0x03
A7: 0x28 | B7: CommunicationControl | C7: 0x00 EnableRxAndTx | D7: Y | E7: Y | F7: Y
C8: 0x01 EnableRxAndDisableTx
C9: 0x02 DisableRxAndEnableTx
C10: 0x03 DisableRxAndTx | D10: Y | E10: Y | F10: Y

Sheet DTCInfo2
A1: Return
A2: Diagnostic Questionnaire - GroupOfDTC
A5: Service ID | B5: DTC Group(hex) | C5: Group Description | D5: Supported by ECU | E5: Remarks | F5: FVT Require
A7: 0x14 | B7: 0xFFFF33 | C7: Emissions-related systems | D7: Y | F7: ZEVonUDS
B8: 0x100000 | C8: Powertrain group | D8: N | F8: U
B9: 0x400000 | C9: Chassis group | D9: N | F9: U
B10: 0x800000 | C10: Body group | D10: N | F10: U
B11: 0xC00000 | C11: Network communication group | D11: N | F11: U
B12: 0xFFFFFF | C12: All DTC group | D12: Y | F12: M
A14: Diagnostic Questionnaire - DTC Status
A17: Bit Field | B17: Bit Description | C17: Bit State Definition | D17: Supported by ECU | E17: Remarks | F17: FVT Require
A18: 0 | B18: Test failed | C18: 0=False 1=True | D18: Y | F18: M | G18: ZEVonUDS
A19: 1 | B19: Test failed this monitoring cycle | C19: 0=False 1=True | D19: Y | F19: ZEVonUDS
A20: 2 | B20: Pending DTC | C20: 0=False 1=True | D20: Y | F20: M | G20: ZEVonUDS
A21: 3 | B21: Confirmed DTC | C21: 0=False 1=True | D21: Y | F21: M | G21: ZEVonUDS
A22: 4 | B22: Test not completed since last clear | C22: 0=False 1=True | D22: Y | F22: ZEVonUDS
A23: 5 | B23: Test failed since last clear | C23: 0=False 1=True | D23: N | F23: U
A24: 6 | B24: Test not completed this monitoring cycle | C24: 0=False 1=True | D24: Y | F24: ZEVonUDS
A25: 7 | B25: Warning indicator requested | C25: 0=False 1=True | D25: N | F25: U
A27: Diagnostic Questionnaire - DTCFormatIdentifier
A28: An ECU shall only support one DTCFormat, i.e., all DTCs in an ECU shall utilize the same DTCFormat.
A30: Byte value | B30: Definition | C30: Description | D30: Supported by ECU | E30: Remarks | F30: FVT Require
A31: 0x01 | B31: ISO_14229-1_DTCForma | C31: This parameter value identifies the DTC format reported by the server as defined in this table by the parameter DTCAndStatusRecord. | D31: N | F31: M
A32: 0x04 | B32: SAE_J2012-DA_DTCFormat_04 | C32: This parameter value identifies the DTC format reported by the server as defined in SAE J2012-DA specification. | D32: Y | F32: ZEVonUDS

Sheet DTCList
A2: Diagnostic Questionnaire - DTC List
A5: DTC Display | B5: DTC Byte (Hex) | C5: DTC Meaning | D5: FVT Require | E5: Diagnostic Tool Normal mode | F5: Diagnostic Tool Engineer mode | G5: Part number & model
G6: D31L | H6: D31L24 | I6: D31F25 | J6: D31H | K6: D21 | L6: Foxtorn Pi | AA6: Functional classification 功能分类
A7: U100901 | B7: 0xD00901 | C7: Lost Communication with EPS | E7: N | F7: N | G7: N | H7: N | I7: N | J7: N | K7: N | L7: N | AA7: APS
A8: U100902 | B8: 0xD00902 | C8: Lost Communication with ESC | E8: N | F8: N | G8: N | H8: N | I8: N | J8: N | K8: N | L8: N | AA8: APS
A9: B100903 | B9: 0x900903 | C9: Battery Voltage too High | E9: N | F9: N | G9: N | H9: N | I9: N | J9: N | K9: N | L9: N | AA9: APS
A10: B100904 | B10: 0x900904 | C10: Battery Voltage too Low | E10: N | F10: N | G10: N | H10: N | I10: N | J10: N | K10: N | L10: N | AA10: APS
A11: B100905 | B11: 0x900905 | C11: Battery Voltage too High | E11: N | F11: N | G11: N | H11: N | I11: N | J11: N | K11: N | L11: N | AA11: APS
A12: B100906 | B12: 0x900906 | C12: Battery Voltage too Low | E12: N | F12: N | G12: N | H12: N | I12: N | J12: N | K12: N | L12: N | AA12: APS
A13: B100907 | B13: 0x900907 | C13: DSI3 Transceiver 1 Failure | E13: N | F13: N | G13: N | H13: N | I13: N | J13: N | K13: N | L13: N | AA13: APS
A14: B100908 | B14: 0x900908 | C14: DSI3 Transceiver 2 Failure | E14: N | F14: N | G14: N | H14: N | I14: N | J14: N | K14: N | L14: N | AA14: APS
A15: B100909 | B15: 0x900909 | C15: FCL USS Status Failure | E15: Y | F15: Y | G15: Y | H15: Y | I15: Y | J15: Y | K15: Y | L15: Y | AA15: APS
A16: B10090A | B16: 0x90090A | C16: FML USS Status Failure | E16: Y | F16: Y | G16: Y | H16: Y | I16: Y | J16: Y | K16: Y | L16: Y | AA16: APS
A17: B10090B | B17: 0x90090B | C17: FMR USS Status Failure | E17: Y | F17: Y | G17: Y | H17: Y | I17: Y | J17: Y | K17: Y | L17: Y | AA17: APS
A18: B10090C | B18: 0x90090C | C18: FCR USS Status Failure | E18: Y | F18: Y | G18: Y | H18: Y | I18: Y | J18: Y | K18: Y | L18: Y | AA18: APS
... A108: B10053D | B108: 0x90053D | C108: Charging pile emergency stop | E108: Y | F108: Y | G108: Y | H108: Y | I108: Y | J108: Y | K108: Y | L108: Y | AA108: EVCC
A109: U100300 | B109: 0xD00300 | C109: CAN 1 bus off failure | D109: M | E109: Y | F109: Y | G109: Y | H109: Y | I109: N | J109: N | K109: N | L109: Y | AA109: FD-M
A110: U100301 | B110: 0xD00301 | C110: CAN 2 bus off failure | E110: Y | F110: Y | G110: Y | H110: Y | I110: N | J110: N | K110: N | L110: Y | AA110: FD-M
A111: U100302 | B111: 0xD00302 | C111: CAN 3 bus off failure | E111: Y | F111: Y | G111: Y | H111: Y | I111: N | J111: N | K111: N | L111: Y | AA111: FD-M
A112: U100303 | B112: 0xD00303 | C112: CAN 4 bus off failure | E112: Y | F112: Y | G112: Y | H112: Y | I112: N | J112: N | K112: N | L112: Y | AA112: FD-M
A113: U100304 | B113: 0xD00304 | C113: CAN 5 bus off failure | E113: Y | F113: Y | G113: Y | H113: Y | I113: N | J113: N | K113: N | L113: Y | AA113: FD-M
A114: U100305 | B114: 0xD00305 | C114: CAN 6 bus off failure | E114: Y | F114: Y | G114: N | H114: Y | I114: N | J114: N | K114: N | L114: Y | AA114: FD-M
A115: U100306 | B115: 0xD00306 | C115: CAN GBDC bus off failure | E115: Y | F115: Y | G115: Y | H115: Y | I115: N | J115: N | K115: N | L115: Y | AA115: FD-M
A116: B100307 | B116: 0x900307 | C116: Battery Voltage too High | E116: Y | F116: Y | G116: Y | H116: Y | I116: Y | J116: Y | K116: Y | L116: Y | AA116: FD-M
A117: B100308 | B117: 0x900308 | C117: Battery Voltage too Low | E117: Y | F117: Y | G117: Y | H117: Y | I117: Y | J117: Y | K117: Y | L117: Y | AA117: FD-M
A118: B100E01 | B118: 0x900E01 | C118: FDC fail safe reset | E118: Y | F118: Y | G118: Y | H118: Y | I118: Y | J118: Y | K118: Y | L118: Y | AA118: FD-M
A119: B100E02 | B119: 0x900E02 | C119: FDC unknow boot reason | E119: Y | F119: Y | G119: Y | H119: Y | I119: Y | J119: Y | K119: Y | L119: Y | AA119: FD-M
A120: B100E03 | B120: 0x900E03 | C120: FDC cold start | E120: Y | F120: Y | G120: Y | H120: Y | I120: Y | J120: Y | K120: Y | L120: Y | AA120: FD-M
A121: B100E04 | B121: 0x900E04 | C121: FDC standby timer wake-up | E121: Y | F121: Y | G121: Y | H121: Y | I121: Y | J121: Y | K121: Y | L121: Y | AA121: FD-M
... A382: U079687 | B382: 0xC79687 | C382: Invalid Data Received From AC/DC Converter Control Module "A" - Missing Message | E382: Y | F382: Y | G382: N | H382: N | I382: Y | J382: Y | K382: Y | L382: N | AA382: ZEV

Sheet DTCData
A2: Diagnostic Specification - DTC Data
A5: No. | B5: ECU Variants | F5: DTC Display | G5: DTC Byte (Hex) | H5: DTC Meaning | I5: DTC Traditional Chinese Meaning | J5: DTC Simplified Chinese Meaning | K5: Possible Fault Causes(English) | L5: Possible Fault Causes(Traditional Chinese) | M5: Possible Fault Causes(Simplified Chinese) | N5: Corrective Action(English) | O5: Corrective Action(Traditional Chinese) | P5: Corrective Action(Simplified Chinese) | Q5: DTC Severity | R5: Faults Attribute | S5: DTC Test Frequency | T5: FRS Bit0 DTC-Detection criteria | U5: FRS Bit0 DTC-Detection window | V5: FRS Bit3 DTC-decision | W5: FRS Bit0 DTC-Pass criteria | X5: FRS Bit0 DTC-Pass window | Y5: FRS Fail safe operation during failure detection | Z5: FRS Fail safe operation after failure decision | AA5: FRS -Release condition during failure detection | AB5: FRS Release condition after failure decision | AC5: Bit3 DTC-Confirm Automatic Fault Recovery | AD5: Special Instruction | AE5: Remarks | AF5: FVT Require | BA5: DCU
E6: Fusion ECU | T6: DTC-Test fail Condition | U6: DTC enable criteria | V6: DTC-Confirmed Condition | W6: DTC-Test pass condition | X6: DTC-Test pass enable criteria | Y6: Action Taken after DTC-Test fail | Z6: Action Taken after DTC-Confirm | AA6: Action Release condition for DTC-Test fail | AB6: Action Release condition for DTC-Confirm | BA6: Functional classification 功能分类 | BB6: Operation cycle | BC6: Failure counter threshold | BD6: Aging counter threshold | BE6: CARB ZEV | BF6: J2012
A7: 1 | E7: N | F7: U100901 | G7: 0xD00901 | H7: Lost Communication with EPS | I7: 與 EPS 失去通訊 | J7: 与 EPS 失去通讯 | K7: 1. CAN_H short to CAN_L 2. CAN_H or CAN_L short to Battery or Ground. 3. Transceiver fail | L7: 1. CAN_H短接CAN_L 2. CAN_H 或 CAN_L 對電池或接地短路。 3. | M7: 1. CAN_H短接CAN_L 2. CAN_H 或 CAN_L 对电池或接地短路。 3. | N7: Check Harness | O7: 檢查線束 | P7: 检查线束 | Q7: 0x40 | R7: Communication type fault | S7: 10ms | T7: Lost Communication with EPS over TBD sec | U7: After vehicle power state ~= OFF | V7: Lost Communication with EPS over TBD sec | W7: Receive EPS Any Frame | X7: Same as detection window. | Y7: Inhibit APS Function | Z7: Inhibit APS Function | AA7: Receive EPS Any Frame | AB7: Receive EPS Any Frame | AC7: A history DTC clears when the module operation cycle counter reaches the reset threshold of 40, without a repeat of the malfunction. | AD7: none | BA7: APS | BB7: DRIVING_CYCLE | BC7: 1 | BD7: 40 | BE7: N | BF7: Manufacturer controlled
A8: 2 | E8: N | F8: U100902 | G8: 0xD00902 | H8: Lost Communication with ESC | I8: 與 ESC 失去通訊 | J8: 与 ESC 失去通讯 | K8: 1. CAN_H short to CAN_L 2. CAN_H or CAN_L short to Battery or Ground. 3. Transceiver fail | L8: 1. CAN_H短接CAN_L 2. CAN_H 或 CAN_L 對電池或接地短路。 3. | M8: 1. CAN_H短接CAN_L 2. CAN_H 或 CAN_L 对电池或接地短路。 3. | N8: Check Harness | O8: 檢查線束 | P8: 检查线束 | Q8: 0x40 | R8: Communication type fault | S8: 10ms | T8: Lost Communication with ESC over TBD sec | U8: Power ON | V8: Lost Communication with ESC over TBD sec | W8: Receive ESC Any Frame | X8: Power ON | Y8: Inhibit APS Function | Z8: Inhibit APS Function | AA8: Receive ESC Any Frame | AB8: Receive ESC Any Frame | AC8: A history DTC clears when the module operation cycle counter reaches the reset threshold of 40, without a repeat of the malfunction. | AD8: none | BA8: APS | BB8: DRIVING_CYCLE | BC8: 1 | BD8: 40 | BE8: N | BF8: Manufacturer controlled
A9: 3 | E9: N | F9: B100903 | G9: 0x900903 | H9: Battery Voltage too High | I9: 輸入電源電壓過高 | J9: 输入电源电压过高 | K9: Power Over Range or disconnected | L9: 供電電源超過範圍或線束斷開 | M9: 供电电源超过范围或线束断开 | N9: Check Power Source | O9: 檢查供電電源 | P9: 检查供电电源 | Q9: 0x20 | R9: Power type fault | S9: 100ms | T9: Battery voltage ≧ 16.5V for 5 sec | U9: Power ON | V9: Battery voltage ≧ 16.5V for 5 sec | W9: Battery voltage <16.0V for 5 sec | X9: Power ON | Y9: Inhibit USS Function | Z9: Inhibit USS Function | AA9: Battery voltage <16.0V for 5 sec | AB9: Battery voltage <16.0V for 5 sec | AC9: A history DTC clears when the module operation cycle counter reaches the reset threshold of 40, without a repeat of the malfunction. | AD9: none | AE9: APS (F29)V_USS_12V_S1 | BA9: APS | BB9: DRIVING_CYCLE | BC9: 1 | BD9: 40 | BE9: N | BF9: Manufacturer controlled
A10: 4 | E10: N | F10: B100904 | G10: 0x900904 | H10: Battery Voltage too Low | I10: 輸入電源電壓過低 | J10: 输入电源电压过低 | K10: Power Over Range or disconnected | L10: 供電電源超過範圍或線束斷開 | M10: 供电电源超过范围或线束断开 | N10: Check Power Source | O10: 檢查供電電源 | P10: 检查供电电源 | Q10: 0x20 | R10: Power type fault | S10: 100ms | T10: Battery voltage ≦ 8.5V for 5 sec | U10: Power ON | V10: Battery voltage ≦ 8.5V for 5 sec | W10: Battery voltage >9.0V for 5 sec | X10: Power ON | Y10: Inhibit USS Function | Z10: Inhibit USS Function | AA10: Battery voltage >9.0V for 5 sec | AB10: Battery voltage >9.0V for 5 sec | AC10: A history DTC clears when the module operation cycle counter reaches the reset threshold of 40, without a repeat of the malfunction. | AD10: none | AE10: APS (F29)V_USS_12V_S1 | BA10: APS | BB10: DRIVING_CYCLE | BC10: 1 | BD10: 40 | BE10: N | BF10: Manufacturer controlled
A11: 5 | E11: N | F11: B100905 | G11: 0x900905 | H11: Battery Voltage too High | I11: 輸入電源電壓過高 | J11: 输入电源电压过高 | K11: Power Over Range or disconnected | L11: 供電電源超過範圍或線束斷開 | M11: 供电电源超过范围或线束断开 | N11: Check Power Source | O11: 檢查供電電源 | P11: 检查供电电源 | Q11: 0x20 | R11: Power type fault | S11: 100ms | T11: Battery voltage ≧ 16.5V for 5 sec | U11: Power ON | V11: Battery voltage ≧ 16.5V for 5 sec | W11: Battery voltage <16.0V for 5 sec | X11: Power ON | Y11: Inhibit USS Function | Z11: Inhibit USS Function | AA11: Battery voltage <16.0V for 5 sec | AB11: Battery voltage <16.0V for 5 sec | AC11: A history DTC clears when the module operation cycle counter reaches the reset threshold of 40, without a repeat of the malfunction. | AD11: none | AE11: APS (B29)V_USS_12V_S2 | BA11: APS | BB11: DRIVING_CYCLE | BC11: 1 | BD11: 40 | BE11: N | BF11: Manufacturer controlled
A12: 6 | E12: N | F12: B100906 | G12: 0x900906 | H12: Battery Voltage too Low | I12: 電源失效 (USS_DSI3 & USS_DSI4會失效) | J12: 电源失效 | K12: Power Over Range or disconnected | L12: 供電電源超過範圍或線束斷開 | M12: 供电电源超过范围或线束断开 | N12: Check Power Source | O12: 檢查供電電源 | P12: 检查供电电源 | Q12: 0x20 | R12: Power type fault | S12: 100ms | T12: Battery voltage ≦ 8.5V for 5 sec | U12: Power ON | V12: Battery voltage ≦ 8.5V for 5 sec | W12: Battery voltage >9.0V for 5 sec | X12: Power ON | Y12: Inhibit USS Function | Z12: Inhibit USS Function | AA12: Battery voltage >9.0V for 5 sec | AB12: Battery voltage >9.0V for 5 sec | AC12: A history DTC clears when the module operation cycle counter reaches the reset threshold of 40, without a repeat of the malfunction. | AD12: none | AE12: APS (B29)V_USS_12V_S2 | BA12: APS | BB12: DRIVING_CYCLE | BC12: 1 | BD12: 40 | BE12: N | BF12: Manufacturer controlled
A13: 7 | E13: N | F13: B100907 | G13: 0x900907 | H13: DSI3 Transceiver 1 Failure | I13: DSI3 收發器 1 失效 | J13: DSI3 收发器 1 失效 | K13: Transceiver fail | L13: 收發器異常 | M13: 收发器异常 | N13: Check Harness | O13: 1. 換件查修 2. 檢查線束 | P13: 检查线束 | Q13: 0x80 | R13: Sensor type fault | S13: 40ms | T13: Any DSI3 IC Status Word Signal Error | U13: Power ON | V13: Any DSI3 IC Status Word Signal Error | W13: All DSI3 IC Status Word Signal Normal | X13: Power ON | Y13: Inhibit USS Function | Z13: Inhibit USS Function | AA13: All DSI3 IC Status Word Signal Normal | AB13: All DSI3 IC Status Word Signal Normal | AC13: A history DTC clears when the module operation cycle counter reaches the reset threshold of 40, without a repeat of the malfunction. | AD13: none | BA13: APS | BB13: DRIVING_CYCLE | BC13: 1 | BD13: 40 | BE13: N | BF13: Manufacturer controlled
A14: 8 | E14: N | F14: B100908 | G14: 0x900908 | H14: DSI3 Transceiver 2 Failure | I14: DSI3 收發器 2 失效 | J14: DSI3 收发器 2 失效 | K14: Transceiver fail | L14: 收發器異常 | M14: 收发器异常 | N14: Check Harness | O14: 檢查線束 | P14: 检查线束 | Q14: 0x80 | R14: Sensor type fault | S14: 40ms | T14: Any DSI3 IC Status Word Signal Error | U14: Power ON | V14: Any DSI3 IC Status Word Signal Error | W14: All DSI3 IC Status Word Signal Normal | X14: Power ON | Y14: Inhibit USS Function | Z14: Inhibit USS Function | AA14: All DSI3 IC Status Word Signal Normal | AB14: All DSI3 IC Status Word Signal Normal | AC14: A history DTC clears when the module operation cycle counter reaches the reset threshold of 40, without a repeat of the malfunction. | AD14: none | BA14: APS | BB14: DRIVING_CYCLE | BC14: 1 | BD14: 40 | BE14: N | BF14: Manufacturer controlled
A15: 9 | E15: Y | F15: B100909 | G15: 0x900909 | H15: FCL USS Status Failure | I15: FCL 超聲波傳感器異常 | J15: FCL 超声波传感器异常 | K15: 1. Harness disconnected 2. FCL fault | L15: 1. 線束斷開 2. FCL 損壞 | M15: 1. 线束断开 2. FCL 损坏 | N15: 1. Check the harness. 2. Replace the FCL and check the function is normal or not. | O15: 1. 檢查 FCL 線束 2. FCL 換件後，確認功能是否正常。 | P15: 1. 检查 FCL 线束 2. FCL 换件后，确认功能是否正常。 | Q15: 0x80 | R15: Sensor type fault | S15: 40ms | T15: FCL USS Hardware or Communcation Error | U15: Power ON | V15: FCL USS Hardware or Communcation Error | W15: FCL USS Receive Response Frame | X15: Power ON | Y15: Inhibit USS Function | Z15: Inhibit USS Function | AA15: FCL USS Receive Response Frame | AB15: FCL USS Receive Response Frame | AC15: A history DTC clears when the module operation cycle counter reaches the reset threshold of 40, without a repeat of the malfunction. | AD15: none | BA15: APS | BB15: DRIVING_CYCLE | BC15: 1 | BD15: 40 | BE15: N | BF15: Manufacturer controlled
A16: 10 | E16: Y | F16: B10090A | G16: 0x90090A | H16: FML USS Status Failure | I16: FML 超聲波傳感器異常 | J16: FML 超声波传感器异常 | K16: 1. Harness disconnected 2. FML fault | L16: 1. 線束斷開 2. FML 損壞 | M16: 1. 线束断开 2. FML 损坏 | N16: 1. Check the harness. 2. Replace the FML and check the function is normal or not. | O16: 1. 檢查 FML 線束 2. FML 換件後，確認功能是否正常。 | P16: 1. 检查 FCL 线束 2. FCL 换件后，确认功能是否正常。 | Q16: 0x80 | R16: Sensor type fault | S16: 40ms | T16: FML USS Hardware or Communcation Error | U16: Power ON | V16: FML USS Hardware or Communcation Error | W16: FML USS Receive Response Frame | X16: Power ON | Y16: Inhibit USS Function | Z16: Inhibit USS Function | AA16: FML USS Receive Response Frame | AB16: FML USS Receive Response Frame | AC16: A history DTC clears when the module operation cycle counter reaches the reset threshold of 40, without a repeat of the malfunction. | AD16: none | BA16: APS | BB16: DRIVING_CYCLE | BC16: 1 | BD16: 40 | BE16: N | BF16: Manufacturer controlled
A17: 11 | E17: Y | F17: B10090B | G17: 0x90090B | H17: FMR USS Status Failure | I17: FMR 超聲波傳感器異常 | J17: FMR 超声波传感器异常 | K17: 1. Harness disconnected 2. FMR fault | L17: 1. 線束斷開 2. FMR 損壞 | M17: 1. 线束断开 2. FMR 损坏 | N17: 1. Check the harness. 2. Replace the FMR and check the function is normal or not. | O17: 1. 檢查 FMR 線束 2. FMR 換件後，確認功能是否正常。 | P17: 1. 检查 FCL 线束 2. FCL 换件后，确认功能是否正常。 | Q17: 0x80 | R17: Sensor type fault | S17: 40ms | T17: FMR USS Hardware or Communcation Error | U17: Power ON | V17: FMR USS Hardware or Communcation Error | W17: FMR USS Receive Response Frame | X17: Power ON | Y17: Inhibit USS Function | Z17: Inhibit USS Function | AA17: FMR USS Receive Response Frame | AB17: FMR USS Receive Response Frame | AC17: A history DTC clears when the module operation cycle counter reaches the reset threshold of 40, without a repeat of the malfunction. | AD17: none | BA17: APS | BB17: DRIVING_CYCLE | BC17: 1 | BD17: 40 | BE17: N | BF17: Manufacturer controlled
A18: 12 | E18: Y | F18: B10090C | G18: 0x90090C | H18: FCR USS Status Failure | I18: FCR 超聲波傳感器異常 | J18: FCR 超声波传感器异常 | K18: 1. Harness disconnected 2. FCR fault | L18: 1. 線束斷開 2. FCR 損壞 | M18: 1. 线束断开 2. FCR 损坏 | N18: 1. Check the harness. 2. Replace the FCR and check the function is normal or not. | O18: 1. 檢查 FCR 線束 2. FCR 換件後，確認功能是否正常。 | P18: 1. 检查 FCL 线束 2. FCL 换件后，确认功能是否正常。 | Q18: 0x80 | R18: Sensor type fault | S18: 40ms | T18: FCR USS Hardware or Communcation Error | U18: Power ON | V18: FCR USS Hardware or Communcation Error | W18: FCR USS Receive Response Frame | X18: Power ON | Y18: Inhibit USS Function | Z18: Inhibit USS Function | AA18: FCR USS Receive Response Frame | AB18: FCR USS Receive Response Frame | AC18: A history DTC clears when the module operation cycle counter reaches the reset threshold of 40, without a repeat of the malfunction. | AD18: none | BA18: APS | BB18: DRIVING_CYCLE | BC18: 1 | BD18: 40 | BE18: N | BF18: Manufacturer controlled
A19: 13 | E19: Y | F19: B10090D | G19: 0x90090D | H19: RCL USS Status Failure | I19: RCL 超聲波傳感器異常 | J19: RCL 超声波传感器异常 | K19: 1. Harness disconnected 2. RCL fault | L19: 1. 線束斷開 2. RCL 損壞 | M19: 1. 线束断开 2. RCL 损坏 | N19: 1. Check the harness. 2. Replace the RCL and check the function is normal or not. | O19: 1. 檢查 RCL 線束 2. RCL 換件後，確認功能是否正常。 | P19: 1. 检查 FCL 线束 2. FCL 换件后，确认功能是否正常。 | Q19: 0x80 | R19: Sensor type fault | S19: 40ms | T19: RCL USS Hardware or Communcation Error | U19: Power ON | V19: RCL USS Hardware or Communcation Error | W19: RCL USS Receive Response Frame | X19: Power ON | Y19: Inhibit USS Function | Z19: Inhibit USS Function | AA19: RCL USS Receive Response Frame | AB19: RCL USS Receive Response Frame | AC19: A history DTC clears when the module operation cycle counter reaches the reset threshold of 40, without a repeat of the malfunction. | AD19: none | BA19: APS | BB19: DRIVING_CYCLE | BC19: 1 | BD19: 40 | BE19: N | BF19: Manufacturer controlled
A20: 14 | E20: Y | F20: B10090E | G20: 0x90090E | H20: RML USS Status Failure | I20: RML 超聲波傳感器異常 | J20: RML 超声波传感器异常 | K20: 1. Harness disconnected 2. RML fault | L20: 1. 線束斷開 2. RML 損壞 | M20: 1. 线束断开 2. RML 损坏 | N20: 1. Check the harness. 2. Replace the RML and check the function is normal or not. | O20: 1. 檢查 RML 線束 2. RML 換件後，確認功能是否正常。 | P20: 1. 检查 FCL 线束 2. FCL 换件后，确认功能是否正常。 | Q20: 0x80 | R20: Sensor type fault | S20: 40ms | T20: RML USS Hardware or Communcation Error | U20: Power ON | V20: RML USS Hardware or Communcation Error | W20: RML USS Receive Response Frame | X20: Power ON | Y20: Inhibit USS Function | Z20: Inhibit USS Function | AA20: RML USS Receive Response Frame | AB20: RML USS Receive Response Frame | AC20: A history DTC clears when the module operation cycle counter reaches the reset threshold of 40, without a repeat of the malfunction. | AD20: none | BA20: APS | BB20: DRIVING_CYCLE | BC20: 1 | BD20: 40 | BE20: N | BF20: Manufacturer controlled
A21: 15 | E21: Y | F21: B10090F | G21: 0x90090F | H21: RMR USS Status Failure | I21: RMR 超聲波傳感器異常 | J21: RMR 超声波传感器异常 | K21: 1. Harness disconnected 2. RMR fault | L21: 1. 線束斷開 2. RMR 損壞 | M21: 1. 线束断开 2. RMR 损坏 | N21: 1. Check the harness. 2. Replace the RMR and check the function is normal or not. | O21: 1. 檢查 RMR 線束 2. RMR 換件後，確認功能是否正常。 | P21: 1. 检查 FCL 线束 2. FCL 换件后，确认功能是否正常。 | Q21: 0x80 | R21: Sensor type fault | S21: 40ms | T21: RMR USS Hardware or Communcation Error | U21: Power ON | V21: RMR USS Hardware or Communcation Error | W21: RMR USS Receive Response Frame | X21: Power ON | Y21: Inhibit USS Function | Z21: Inhibit USS Function | AA21: RMR USS Receive Response Frame | AB21: RMR USS Receive Response Frame | AC21: A history DTC clears when the module operation cycle counter reaches the reset threshold of 40, without a repeat of the malfunction. | AD21: none | BA21: APS | BB21: DRIVING_CYCLE | BC21: 1 | BD21: 40 | BE21: N | BF21: Manufacturer controlled
A22: 16 | E22: Y | F22: B100910 | G22: 0x900910 | H22: RCR USS Status Failure | I22: RCR 超聲波傳感器異常 | J22: RCR 超声波传感器异常 | K22: 1. Harness disconnected 2. RCR fault | L22: 1. 線束斷開 2. RCR 損壞 | M22: 1. 线束断开 2. RCR 损坏 | N22: 1. Check the harness. 2. Replace the RCR and check the function is normal or not. | O22: 1. 檢查 RCR 線束 2. RCR 換件後，確認功能是否正常。 | P22: 1. 检查 FCL 线束 2. FCL 换件后，确认功能是否正常。 | Q22: 0x80 | R22: Sensor type fault | S22: 40ms | T22: RCR USS Hardware or Communcation Error | U22: Power ON | V22: RCR USS Hardware or Communcation Error | W22: RCR USS Receive Response Frame | X22: Power ON | Y22: Inhibit USS Function | Z22: Inhibit USS Function | AA22: RCR USS Receive Response Frame | AB22: RCR USS Receive Response Frame | AC22: A history DTC clears when the module operation cycle counter reaches the reset threshold of 40, without a repeat of the malfunction. | AD22: none | BA22: APS | BB22: DRIVING_CYCLE | BC22: 1 | BD22: 40 | BE22: N | BF22: Manufacturer controlled
A23: 17 | E23: Y | F23: B100911 | G23: 0x900911 | H23: FLL USS Status Failure | I23: FLL 超聲波傳感器異常 | J23: FLL 超声波传感器异常 | K23: 1. Harness disconnected 2. FLL fault | L23: 1. 線束斷開 2. FLL 損壞 | M23: 1. 线束断开 2. FLL 损坏 | N23: 1. Check the harness. 2. Replace the FLL and check the function is normal or not. | O23: 1. 檢查 FLL 線束 2. FLL 換件後，確認功能是否正常。 | P23: 1. 检查 FCL 线束 2. FCL 换件后，确认功能是否正常。 | Q23: 0x40 | R23: Sensor type fault | S23: 40ms | T23: FLL USS Hardware or Communcation Error | U23: Power ON | V23: FLL USS Hardware or Communcation Error | W23: FLL USS Receive Response Frame | X23: Power ON | Y23: Inhibit USS Function | Z23: Inhibit USS Function | AA23: FLL USS Receive Response Frame | AB23: FLL USS Receive Response Frame | AC23: A history DTC clears when the module operation cycle counter reaches the reset threshold of 40, without a repeat of the malfunction. | AD23: none | BA23: APS | BB23: DRIVING_CYCLE | BC23: 1 | BD23: 40 | BE23: N | BF23: Manufacturer controlled
A24: 18 | E24: Y | F24: B100912 | G24: 0x900912 | H24: FLR USS Status Failure | I24: FLR 超聲波傳感器異常 | J24: FLR 超声波传感器异常 | K24: 1. Harness disconnected 2. FLR fault | L24: 1. 線束斷開 2. FLR 損壞 | M24: 1. 线束断开 2. FLR 损坏 | N24: 1. Check the harness. 2. Replace the FLR and check the function is normal or not. | O24: 1. 檢查 FLR 線束 2. FLR 換件後，確認功能是否正常。 | P24: 1. 检查 FCL 线束 2. FCL 换件后，确认功能是否正常。 | Q24: 0x40 | R24: Sensor type fault | S24: 40ms | T24: FLR USS Hardware or Communcation Error | U24: Power ON | V24: FLR USS Hardware or Communcation Error | W24: FLR USS Receive Response Frame | X24: Power ON | Y24: Inhibit USS Function | Z24: Inhibit USS Function | AA24: FLR USS Receive Response Frame | AB24: FLR USS Receive Response Frame | AC24: A history DTC clears when the module operation cycle counter reaches the reset threshold of 40, without a repeat of the malfunction. | AD24: none | BA24: APS | BB24: DRIVING_CYCLE | BC24: 1 | BD24: 40 | BE24: N | BF24: Manufacturer controlled
... A47: 41 | E47: Y | F47: U100704 | G47: 0xD00704 | H47: Lost Communication with cloud server | I47: 與雲端伺服器失去通訊 | J47: 与云云服务器失去通讯 | K47: 1.The relevant ECU damage 2.The relevant Cloud damage | L47: 1.相關ECU損壞 2.相關雲端伺服器損壞 | M47: 1.相关ECU损坏 2.相关云云服务器损坏 | N47: none | O47: 無 | P47: 无 | Q47: 0x40 | R47: Communication type fault | S47: <10ms | T47: Lost Communication with cloud server | U47: ECU not in sleep mode. | V47: Lost Communication with cloud server over 500ms | W47: Receive cloud server any response | X47: ECU not in sleep mode. | Y47: none | Z47: none | AA47: none | AB47: none | AC47: A history DTC clears when the module operation cycle counter reaches the reset threshold of 40, without a repeat of the malfunction. | AD47: No | BA47: Connectivity | BB47: WAKEUP_CYCLE | BC47: 1 | BD47: 1 | BE47: N | BF47: Manufacturer controlled
A48: 42 | E48: Y | F48: B100501 | G48: 0x900501 | H48: BMS: B2E message Timeout | I48: BMS: B2E 回應超時 | J48: BMS: B2E 回應超時 | K48: Communication abnormality | L48: 通訊異常 | M48: 通讯异常 | N48: none | O48: 無 | P48: 无 | Q48: 0x20 | R48: Communication type fault | S48: 10ms | T48: Check EVCC is unable to receive BMS's CAN message (B2E 0x144156F4) when BMS_WAKEUP (A+) is high. | U48: communication period (A+ high) | V48: The testFail detected for 10 times. (each system wake-up counts as one cycle) | W48: BMS message received | X48: communication period | Y48: none | Z48: none | AA48: none | AB48: none | AC48: none | AD48: none | BA48: EVCC | BB48: CHARGING_CYCLE | BC48: 1 | BD48: 5 | BE48: N | BF48: Manufacturer controlled
A49: 43 | E49: Y | F49: B100502 | G49: 0x900502 | H49: Unable to enter charging state (S2 switch close failure) | I49: 無法進入充電狀態 (S2接合失敗) | J49: 无法进入充电状态 (S2接合失败) | K49: 1. Fusion hardware abnormality (CP pin abnormality) 2. CP wire circuit abnormality | L49: 1、Fusion硬體異常(CP腳位異常) 2. CP 電線回路異常 | M49: 1、Fusion硬體異常(CP腳位異常) 2. CP 電線回路異常 | N49: 1. Confirm EVSE can charge other vehicles 2. Reconnect the battery. If AC or DC charging fails, replace it with FDC. | O49: 1. 確認EVSE可以對其他車輛充電 2. 重新上下電瓶電，若都無法AC、DC充電則換 FDC | P49: 1. 确认EVSE可以对其他车辆充电 2. 重新上下电瓶电，若都无法AC、DC充电则换 FDC | Q49: 0x20 | R49: Electrical failure | S49: 10ms | T49: After S2 switching, the target state cannot be reached within 10ms | U49: After controlling S2 | V49: The testFail detected for 3 times. (from entering charging to leaving charging is counted as one charge) | W49: reach target state | X49: charging mode | Y49: none | Z49: none | AA49: none | AB49: none | AC49: none | AD49: none | BA49: EVCC | BB49: CHARGING_CYCLE | BC49: 1 | BD49: 5 | BE49: N | BF49: Manufacturer controlled
A50: 44 | E50: Y | F50: B100503 | G50: 0x900503 | H50: Unable to enter charging standby state (S2 switch open failure) | I50: 無法進入充電待命狀態(S2斷開失敗) | J50: 无法进入充电待命状态(S2断开失败) | K50: 1. Fusion hardware abnormality (CP pin abnormality) 2. CP wire circuit abnormality | L50: 1、Fusion硬體異常(CP腳位異常) 2. CP 電線回路異常 | M50: 1、Fusion硬體異常(CP腳位異常) 2. CP 電線回路異常 | N50: 1. Confirm EVSE can charge other vehicles 2. Reconnect the battery. If AC or DC charging fails, replace it with FDC. | O50: 1. 確認EVSE可以對其他車輛充電 2. 重新上下電瓶電，若都無法AC、DC充電則換 FDC | P50: 1. 确认EVSE可以对其他车辆充电 2. 重新上下电瓶电，若都无法AC、DC充电则换 FDC | Q50: 0x20 | R50: Electrical failure | S50: 10ms | T50: After S2 switching, the target state cannot be reached within 10ms | U50: After controlling S2 | V50: The testFail detected for 3 times. (from entering charging to leaving charging is counted as one charge) | W50: reach target state | X50: charging mode | Y50: none | Z50: none | AA50: none | AB50: none | AC50: none | AD50: none | BA50: EVCC | BB50: CHARGING_CYCLE | BC50: 1 | BD50: 5 | BE50: N | BF50: Manufacturer controlled
A51: 45 | E51: Y | F51: B100504 | G51: 0x900504 | H51: PLC module failure | I51: Fusion 內部 PLC通訊模組失效 | J51: Fusion 內部 PLC通訊模組失效 | K51: Fusion hardware exception (PLC module exception) | L51: Fusion硬體異常(PLC模組異常) | M51: Fusion硬體異常(PLC模組異常) | N51: 1. Confirm EVSE can charge other vehicles 2. Reconnect the battery. If AC or DC charging fails, replace it with FDC. | O51: 1. 確認EVSE可以對其他車輛充電 2. 重新上下電瓶電，若都無法AC、DC充電則換 FDC | P51: 1. 确认EVSE可以对其他车辆充电 2. 重新上下电瓶电，若都无法AC、DC充电则换 FDC | Q51: 0x20 | R51: Electrical failure | S51: 10ms | T51: Cannot get PLC firmware version or cannot init PLC module | U51: At EVCC start up | V51: The testFail detected for 3 times. (each system wake-up counts as one cycle) | W51: PLC communication is normal | X51: communication period | Y51: none | Z51: none | AA51: none | AB51: none | AC51: none | AD51: none | BA51: EVCC | BB51: WAKEUP_CYCLE | BC51: 1 | BD51: 5 | BE51: N | BF51: Manufacturer controlled
A52: 46 | E52: Y | F52: B100505 | G52: 0x900505 | H52: PWM detection failure | I52: Fusion 內部 PWM模組失效 | J52: Fusion 內部 PWM模組失效 | K52: Fusion hardware abnormality (PWM module abnormality) | L52: Fusion硬體異常(PWM模組異常) | M52: Fusion硬體異常(PWM模組異常) | N52: 1. Confirm EVSE can charge other vehicles 2. Reconnect the battery. If AC or DC charging fails, replace it with FDC. | O52: 1. 確認EVSE可以對其他車輛充電 2. 重新上下電瓶電，若都無法AC、DC充電則換 FDC | P52: 1. 确认EVSE可以对其他车辆充电 2. 重新上下电瓶电，若都无法AC、DC充电则换 FDC | Q52: 0x20 | R52: Electrical failure | S52: 10ms | T52: Unable to initiate the PWM capture function | U52: After starting PWM detection | V52: The testFail detected for 3 times. (each system wake-up counts as one cycle) | W52: Complete the PWM start-up configuration | X52: After starting PWM detection | Y52: none | Z52: none | AA52: none | AB52: none | AC52: none | AD52: none | BA52: EVCC | BB52: WAKEUP_CYCLE | BC52: 1 | BD52: 5 | BE52: N | BF52: Manufacturer controlled
A53: 47 | E53: N | F53: B100506 | G53: 0x900506 | H53: PLC transmission abnormality | I53: PLC 訊號傳送異常 | J53: PLC 訊號傳送異常 | K53: 1. PLC module abnormality 2. External surge interference | L53: 1. PLC模組異常 2. 外部突波干擾 | M53: 1. PLC模組異常 2. 外部突波干擾 | N53: Recharging and powering off the battery | O53: 電瓶重新上下電 | P53: 電瓶重新上下電 | Q53: 0x20 | R53: Electrical failure | S53: 10ms | T53: PLC is not responding and re-try fail | U53: When charging | V53: The testFail detected for 1 times. (from entering charging to leaving charging is counted as one charge) | W53: PLC transmission is normal | X53: communication period | Y53: none | Z53: none | AA53: none | AB53: none | AC53: none | AD53: none | BA53: EVCC | BB53: WAKEUP_CYCLE | BC53: 1 | BD53: 5 | BE53: N | BF53: Manufacturer controlled
A54: 48 | E54: Y | F54: B100507 | G54: 0x900507 | H54: BMS communication abnormality | I54: BMS通訊異常 | J54: BMS通訊異常 | K54: BMS communication handover abnormal | L54: BMS通訊交握異常 | M54: BMS通訊交握異常 | N54: none | O54: 無 | P54: 無 | Q54: 0x20 | R54: Communication type fault | S54: 500ms | T54: No B2E signal BmsChoiceChargeMode=DC 5 second timeout | U54: When charging | V54: The testFail detected for 3 times. (from entering charging to leaving charging is counted as one charge) | W54: Communication with BMS is normal | X54: communication period | Y54: none | Z54: none | AA54: none | AB54: none | AC54: none | AD54: none | BA54: EVCC | BB54: CHARGING_CYCLE | BC54: 1 | BD54: 5 | BE54: N | BF54: Manufacturer controlled
A55: 49 | E55: Y | F55: B100508 | G55: 0x900508 | H55: BMS_WAKEUP Unable to set high position | I55: BMS_WAKEUP 信號無法設定高凖位 | J55: BMS_WAKEUP 信号无法设定高凖位 | K55: 1. Fusionu hardware abnormality (BMS_WAKEUP pin abnormality) 2. BMS_WAKEUP wire circuit abnormality | L55: 1、Fusionu硬體異常 2. BMS_WAKEUP電線迴路異常 | M55: 1、Fusionu硬件异常 2. BMS_WAKEUP电线回路异常 | N55: 1. Confirm EVSE can charge other vehicles 2. Reconnect the battery. If AC or DC charging fails, replace it with FDC. | O55: 1. 確認EVSE可以對其他車輛充電 2. 重新上下電瓶電，若都無法AC、DC充電則換 FDC | P55: 1. 确认EVSE可以对其他车辆充电 2. 重新上下电瓶电，若都无法AC、DC充电则换 FDC | Q55: 0x20 | R55: Electrical failure | S55: 10ms | T55: After BMS_WAKEUP (A+) switching, the target state cannot be reached within 10ms | U55: When changing A+ status | V55: The testFail detected for 3 times. (from entering charging to leaving charging is counted as one charge) | W55: reach target state | X55: charging mode | Y55: none | Z55: none | AA55: none | AB55: none | AC55: none | AD55: none | BA55: EVCC | BB55: CHARGING_CYCLE | BC55: 1 | BD55: 5 | BE55: N | BF55: Manufacturer controlled
